<?xml version="1.0" ?>
<robot name="deliverybot" xmlns:xacro="http://www.ros.org/wiki/xacro">

<xacro:include filename="$(find deliverybot_description)/urdf/materials.xacro" />
<xacro:include filename="$(find deliverybot_description)/urdf/deliverybot.trans" />
<xacro:include filename="$(find deliverybot_description)/urdf/deliverybot.gazebo" />
<link name="base_link">
  <inertial>
    <origin xyz="2.0576851223912385e-14 0.0 0.07094584265517533" rpy="0 0 0"/>
    <mass value="0.6601431395428371"/>
    <inertia ixx="0.001257" iyy="0.002184" izz="0.003357" ixy="0.0" iyz="0.0" ixz="0.0"/>
  </inertial>
  <visual>
    <origin xyz="0 0 0" rpy="0 0 0"/>
    <geometry>
      <mesh filename="package://deliverybot_description/meshes/base_link.stl" scale="0.001 0.001 0.001"/>
    </geometry>
    <material name="silver"/>
  </visual>
  <collision>
    <origin xyz="0 0 0" rpy="0 0 0"/>
    <geometry>
      <mesh filename="package://deliverybot_description/meshes/base_link.stl" scale="0.001 0.001 0.001"/>
    </geometry>
  </collision>
</link>

<link name="frontl1_1">
  <inertial>
    <origin xyz="0.01546773975084105 0.0011589732013603665 -0.02477278912176316" rpy="0 0 0"/>
    <mass value="0.009898876641599642"/>
    <inertia ixx="2e-06" iyy="3e-06" izz="1e-06" ixy="0.0" iyz="-0.0" ixz="1e-06"/>
  </inertial>
  <visual>
    <origin xyz="-0.08 0.085 -0.07" rpy="0 0 0"/>
    <geometry>
      <mesh filename="package://deliverybot_description/meshes/frontl1_1.stl" scale="0.001 0.001 0.001"/>
    </geometry>
    <material name="silver"/>
  </visual>
  <collision>
    <origin xyz="-0.08 0.085 -0.07" rpy="0 0 0"/>
    <geometry>
      <mesh filename="package://deliverybot_description/meshes/frontl1_1.stl" scale="0.001 0.001 0.001"/>
    </geometry>
  </collision>
</link>

<link name="backl1_1">
  <inertial>
    <origin xyz="-0.015467739750841036 0.0011589732013603665 -0.02477278912176316" rpy="0 0 0"/>
    <mass value="0.009898876641599642"/>
    <inertia ixx="2e-06" iyy="3e-06" izz="1e-06" ixy="-0.0" iyz="-0.0" ixz="-1e-06"/>
  </inertial>
  <visual>
    <origin xyz="0.08 0.085 -0.07" rpy="0 0 0"/>
    <geometry>
      <mesh filename="package://deliverybot_description/meshes/backl1_1.stl" scale="0.001 0.001 0.001"/>
    </geometry>
    <material name="silver"/>
  </visual>
  <collision>
    <origin xyz="0.08 0.085 -0.07" rpy="0 0 0"/>
    <geometry>
      <mesh filename="package://deliverybot_description/meshes/backl1_1.stl" scale="0.001 0.001 0.001"/>
    </geometry>
  </collision>
</link>

<link name="frontl2_1">
  <inertial>
    <origin xyz="0.015467739750753023 -0.0011589732013603943 -0.02477278912176304" rpy="0 0 0"/>
    <mass value="0.009898876641599573"/>
    <inertia ixx="2e-06" iyy="3e-06" izz="1e-06" ixy="-0.0" iyz="0.0" ixz="1e-06"/>
  </inertial>
  <visual>
    <origin xyz="-0.08 -0.085 -0.07" rpy="0 0 0"/>
    <geometry>
      <mesh filename="package://deliverybot_description/meshes/frontl2_1.stl" scale="0.001 0.001 0.001"/>
    </geometry>
    <material name="silver"/>
  </visual>
  <collision>
    <origin xyz="-0.08 -0.085 -0.07" rpy="0 0 0"/>
    <geometry>
      <mesh filename="package://deliverybot_description/meshes/frontl2_1.stl" scale="0.001 0.001 0.001"/>
    </geometry>
  </collision>
</link>

<link name="backl2_1">
  <inertial>
    <origin xyz="-0.015467739750753023 -0.0011589732013603943 -0.02477278912176304" rpy="0 0 0"/>
    <mass value="0.009898876641599573"/>
    <inertia ixx="2e-06" iyy="3e-06" izz="1e-06" ixy="0.0" iyz="0.0" ixz="-1e-06"/>
  </inertial>
  <visual>
    <origin xyz="0.08 -0.085 -0.07" rpy="0 0 0"/>
    <geometry>
      <mesh filename="package://deliverybot_description/meshes/backl2_1.stl" scale="0.001 0.001 0.001"/>
    </geometry>
    <material name="silver"/>
  </visual>
  <collision>
    <origin xyz="0.08 -0.085 -0.07" rpy="0 0 0"/>
    <geometry>
      <mesh filename="package://deliverybot_description/meshes/backl2_1.stl" scale="0.001 0.001 0.001"/>
    </geometry>
  </collision>
</link>

<link name="lidar_1">
  <inertial>
    <origin xyz="-3.618764437576268e-18 -7.237528875152536e-18 0.0049999999999999906" rpy="0 0 0"/>
    <mass value="0.02081305133003238"/>
    <inertia ixx="3e-06" iyy="3e-06" izz="7e-06" ixy="-0.0" iyz="-0.0" ixz="-0.0"/>
  </inertial>
  <visual>
    <origin xyz="-0.0 -0.0 -0.12" rpy="0 0 0"/>
    <geometry>
      <mesh filename="package://deliverybot_description/meshes/lidar_1.stl" scale="0.001 0.001 0.001"/>
    </geometry>
    <material name="silver"/>
  </visual>
  <collision>
    <origin xyz="-0.0 -0.0 -0.12" rpy="0 0 0"/>
    <geometry>
      <mesh filename="package://deliverybot_description/meshes/lidar_1.stl" scale="0.001 0.001 0.001"/>
    </geometry>
  </collision>
</link>

<link name="camera_1">
  <inertial>
    <origin xyz="-0.020073425871742517 4.7255862113405526e-15 0.0050000000000000044" rpy="0 0 0"/>
    <mass value="0.00235835929429756"/>
    <inertia ixx="0.0" iyy="0.0" izz="0.0" ixy="-0.0" iyz="-0.0" ixz="0.0"/>
  </inertial>
  <visual>
    <origin xyz="-0.1 -0.0 -0.08" rpy="0 0 0"/>
    <geometry>
      <mesh filename="package://deliverybot_description/meshes/camera_1.stl" scale="0.001 0.001 0.001"/>
    </geometry>
    <material name="silver"/>
  </visual>
  <collision>
    <origin xyz="-0.1 -0.0 -0.08" rpy="0 0 0"/>
    <geometry>
      <mesh filename="package://deliverybot_description/meshes/camera_1.stl" scale="0.001 0.001 0.001"/>
    </geometry>
  </collision>
</link>

<link name="front_wheel_1_1">
  <inertial>
    <origin xyz="-1.491862189340054e-14 -0.09499999999999999 -3.469446951953614e-18" rpy="0 0 0"/>
    <mass value="0.05112942043717382"/>
    <inertia ixx="1.4e-05" iyy="2.4e-05" izz="1.4e-05" ixy="0.0" iyz="0.0" ixz="0.0"/>
  </inertial>
  <visual>
    <origin xyz="-0.105 0.006 -0.03" rpy="0 0 0"/>
    <geometry>
      <mesh filename="package://deliverybot_description/meshes/front_wheel_1_1.stl" scale="0.001 0.001 0.001"/>
    </geometry>
    <material name="silver"/>
  </visual>
  <collision>
    <origin xyz="-0.105 0.006 -0.03" rpy="0 0 0"/>
    <geometry>
      <mesh filename="package://deliverybot_description/meshes/front_wheel_1_1.stl" scale="0.001 0.001 0.001"/>
    </geometry>
  </collision>
</link>

<link name="front_wheel_2_1">
  <inertial>
    <origin xyz="-1.491862189340054e-14 0.05499999999999998 0.0" rpy="0 0 0"/>
    <mass value="0.051129420437173806"/>
    <inertia ixx="1.4e-05" iyy="2.4e-05" izz="1.4e-05" ixy="-0.0" iyz="-0.0" ixz="0.0"/>
  </inertial>
  <visual>
    <origin xyz="-0.105 -0.046 -0.03" rpy="0 0 0"/>
    <geometry>
      <mesh filename="package://deliverybot_description/meshes/front_wheel_2_1.stl" scale="0.001 0.001 0.001"/>
    </geometry>
    <material name="silver"/>
  </visual>
  <collision>
    <origin xyz="-0.105 -0.046 -0.03" rpy="0 0 0"/>
    <geometry>
      <mesh filename="package://deliverybot_description/meshes/front_wheel_2_1.stl" scale="0.001 0.001 0.001"/>
    </geometry>
  </collision>
</link>

<link name="back_wheel_1_1">
  <inertial>
    <origin xyz="1.491862189340054e-14 -0.06499999999999997 -3.469446951953614e-18" rpy="0 0 0"/>
    <mass value="0.05112942043717382"/>
    <inertia ixx="1.4e-05" iyy="2.4e-05" izz="1.4e-05" ixy="0.0" iyz="0.0" ixz="-0.0"/>
  </inertial>
  <visual>
    <origin xyz="0.105 0.036 -0.03" rpy="0 0 0"/>
    <geometry>
      <mesh filename="package://deliverybot_description/meshes/back_wheel_1_1.stl" scale="0.001 0.001 0.001"/>
    </geometry>
    <material name="silver"/>
  </visual>
  <collision>
    <origin xyz="0.105 0.036 -0.03" rpy="0 0 0"/>
    <geometry>
      <mesh filename="package://deliverybot_description/meshes/back_wheel_1_1.stl" scale="0.001 0.001 0.001"/>
    </geometry>
  </collision>
</link>

<link name="back_wheel_2_1">
  <inertial>
    <origin xyz="1.491862189340054e-14 0.04499999999999998 -3.469446951953614e-18" rpy="0 0 0"/>
    <mass value="0.05112942043717382"/>
    <inertia ixx="1.4e-05" iyy="2.4e-05" izz="1.4e-05" ixy="0.0" iyz="-0.0" ixz="0.0"/>
  </inertial>
  <visual>
    <origin xyz="0.105 -0.056 -0.03" rpy="0 0 0"/>
    <geometry>
      <mesh filename="package://deliverybot_description/meshes/back_wheel_2_1.stl" scale="0.001 0.001 0.001"/>
    </geometry>
    <material name="silver"/>
  </visual>
  <collision>
    <origin xyz="0.105 -0.056 -0.03" rpy="0 0 0"/>
    <geometry>
      <mesh filename="package://deliverybot_description/meshes/back_wheel_2_1.stl" scale="0.001 0.001 0.001"/>
    </geometry>
  </collision>
</link>

<joint name="Rigid5" type="fixed">
  <origin xyz="0.08 -0.085 0.07" rpy="0 0 0"/>
  <parent link="base_link"/>
  <child link="frontl1_1"/>
</joint>

<joint name="Rigid6" type="fixed">
  <origin xyz="-0.08 -0.085 0.07" rpy="0 0 0"/>
  <parent link="base_link"/>
  <child link="backl1_1"/>
</joint>

<joint name="Rigid7" type="fixed">
  <origin xyz="0.08 0.085 0.07" rpy="0 0 0"/>
  <parent link="base_link"/>
  <child link="frontl2_1"/>
</joint>

<joint name="Rigid8" type="fixed">
  <origin xyz="-0.08 0.085 0.07" rpy="0 0 0"/>
  <parent link="base_link"/>
  <child link="backl2_1"/>
</joint>

<joint name="Rigid9" type="fixed">
  <origin xyz="0.0 0.0 0.12" rpy="0 0 0"/>
  <parent link="base_link"/>
  <child link="lidar_1"/>
</joint>

<joint name="Rigid10" type="fixed">
  <origin xyz="0.1 0.0 0.08" rpy="0 0 0"/>
  <parent link="base_link"/>
  <child link="camera_1"/>
</joint>

<joint name="Revolute1" type="continuous">
  <origin xyz="0.025 0.079 -0.04" rpy="0 0 0"/>
  <parent link="frontl1_1"/>
  <child link="front_wheel_1_1"/>
  <axis xyz="0.0 1.0 0.0"/>
 
</joint>

<joint name="Revolute2" type="continuous">
  <origin xyz="0.025 -0.039 -0.04" rpy="0 0 0"/>
  <parent link="frontl2_1"/>
  <child link="front_wheel_2_1"/>
  <axis xyz="0.0 1.0 0.0"/>
 
</joint>

<joint name="Revolute3" type="continuous">
  <origin xyz="-0.025 0.049 -0.04" rpy="0 0 0"/>
  <parent link="backl1_1"/>
  <child link="back_wheel_1_1"/>
  <axis xyz="0.0 1.0 0.0"/>
 
</joint>

<joint name="Revolute4" type="continuous">
  <origin xyz="-0.025 -0.029 -0.04" rpy="0 0 0"/>
  <parent link="backl2_1"/>
  <child link="back_wheel_2_1"/>
  <axis xyz="0.0 1.0 0.0"/>
</joint>

</robot>
